2021-05-16 03:22:30,740 root         INFO     pyDEA started as a GUI application.
2021-05-16 03:25:29,380 root         INFO     pyDEA started as a GUI application.
2021-05-16 03:27:35,555 root         ERROR    ['Traceback (most recent call last):\n', '  File "C:\\ProgramData\\Anaconda3\\envs\\Recommandation\\lib\\tkinter\\__init__.py", line 1705, in __call__\n    return self.func(*args)\n', '  File "C:\\Users\\Lenovo\\Documents\\git\\ntunhs_2020\\alg_20210610\\pyDEA\\pyDEA\\core\\gui_modules\\data_tab_frame_gui.py", line 247, in load_file\n    self.show_loaded_data(file_name)\n', '  File "C:\\Users\\Lenovo\\Documents\\git\\ntunhs_2020\\alg_20210610\\pyDEA\\pyDEA\\core\\gui_modules\\data_tab_frame_gui.py", line 337, in show_loaded_data\n    self.show_data(categories, coefficients, dmu_name)\n', '  File "C:\\Users\\Lenovo\\Documents\\git\\ntunhs_2020\\alg_20210610\\pyDEA\\pyDEA\\core\\gui_modules\\data_tab_frame_gui.py", line 374, in show_data\n    self.table.cells[0][0].insert(0, dmu_name)\n', '  File "C:\\ProgramData\\Anaconda3\\envs\\Recommandation\\lib\\tkinter\\__init__.py", line 2692, in insert\n    self.tk.call(self._w, \'insert\', index, string)\n', '_tkinter.TclError: wrong # args: should be ".!mainframe.!dataframe.!datatabframe.!labelframe.!tableframewithinputoutputbox.!styledcanvas.!frame.!selfvalidatingentry insert index text"\n']
2021-05-16 03:28:15,368 root         ERROR    ['Traceback (most recent call last):\n', '  File "C:\\ProgramData\\Anaconda3\\envs\\Recommandation\\lib\\tkinter\\__init__.py", line 1705, in __call__\n    return self.func(*args)\n', '  File "C:\\Users\\Lenovo\\Documents\\git\\ntunhs_2020\\alg_20210610\\pyDEA\\pyDEA\\core\\gui_modules\\data_tab_frame_gui.py", line 247, in load_file\n    self.show_loaded_data(file_name)\n', '  File "C:\\Users\\Lenovo\\Documents\\git\\ntunhs_2020\\alg_20210610\\pyDEA\\pyDEA\\core\\gui_modules\\data_tab_frame_gui.py", line 337, in show_loaded_data\n    self.show_data(categories, coefficients, dmu_name)\n', '  File "C:\\Users\\Lenovo\\Documents\\git\\ntunhs_2020\\alg_20210610\\pyDEA\\pyDEA\\core\\gui_modules\\data_tab_frame_gui.py", line 374, in show_data\n    self.table.cells[0][0].insert(0, dmu_name)\n', '  File "C:\\ProgramData\\Anaconda3\\envs\\Recommandation\\lib\\tkinter\\__init__.py", line 2692, in insert\n    self.tk.call(self._w, \'insert\', index, string)\n', '_tkinter.TclError: wrong # args: should be ".!mainframe.!dataframe.!datatabframe.!labelframe.!tableframewithinputoutputbox.!styledcanvas.!frame.!selfvalidatingentry insert index text"\n']
2021-05-16 03:28:21,339 root         ERROR    ['Traceback (most recent call last):\n', '  File "C:\\ProgramData\\Anaconda3\\envs\\Recommandation\\lib\\tkinter\\__init__.py", line 1705, in __call__\n    return self.func(*args)\n', '  File "C:\\Users\\Lenovo\\Documents\\git\\ntunhs_2020\\alg_20210610\\pyDEA\\pyDEA\\core\\gui_modules\\data_tab_frame_gui.py", line 247, in load_file\n    self.show_loaded_data(file_name)\n', '  File "C:\\Users\\Lenovo\\Documents\\git\\ntunhs_2020\\alg_20210610\\pyDEA\\pyDEA\\core\\gui_modules\\data_tab_frame_gui.py", line 337, in show_loaded_data\n    self.show_data(categories, coefficients, dmu_name)\n', '  File "C:\\Users\\Lenovo\\Documents\\git\\ntunhs_2020\\alg_20210610\\pyDEA\\pyDEA\\core\\gui_modules\\data_tab_frame_gui.py", line 374, in show_data\n    self.table.cells[0][0].insert(0, dmu_name)\n', '  File "C:\\ProgramData\\Anaconda3\\envs\\Recommandation\\lib\\tkinter\\__init__.py", line 2692, in insert\n    self.tk.call(self._w, \'insert\', index, string)\n', '_tkinter.TclError: wrong # args: should be ".!mainframe.!dataframe.!datatabframe.!labelframe.!tableframewithinputoutputbox.!styledcanvas.!frame.!selfvalidatingentry insert index text"\n']
2021-05-16 03:28:45,425 root         ERROR    ['Traceback (most recent call last):\n', '  File "C:\\ProgramData\\Anaconda3\\envs\\Recommandation\\lib\\tkinter\\__init__.py", line 1705, in __call__\n    return self.func(*args)\n', '  File "C:\\Users\\Lenovo\\Documents\\git\\ntunhs_2020\\alg_20210610\\pyDEA\\pyDEA\\core\\gui_modules\\data_tab_frame_gui.py", line 247, in load_file\n    self.show_loaded_data(file_name)\n', '  File "C:\\Users\\Lenovo\\Documents\\git\\ntunhs_2020\\alg_20210610\\pyDEA\\pyDEA\\core\\gui_modules\\data_tab_frame_gui.py", line 337, in show_loaded_data\n    self.show_data(categories, coefficients, dmu_name)\n', '  File "C:\\Users\\Lenovo\\Documents\\git\\ntunhs_2020\\alg_20210610\\pyDEA\\pyDEA\\core\\gui_modules\\data_tab_frame_gui.py", line 374, in show_data\n    self.table.cells[0][0].insert(0, dmu_name)\n', '  File "C:\\ProgramData\\Anaconda3\\envs\\Recommandation\\lib\\tkinter\\__init__.py", line 2692, in insert\n    self.tk.call(self._w, \'insert\', index, string)\n', '_tkinter.TclError: wrong # args: should be ".!mainframe.!dataframe.!datatabframe.!labelframe.!tableframewithinputoutputbox.!styledcanvas.!frame.!selfvalidatingentry insert index text"\n']
2021-05-16 03:29:20,346 root         ERROR    ['Traceback (most recent call last):\n', '  File "C:\\ProgramData\\Anaconda3\\envs\\Recommandation\\lib\\tkinter\\__init__.py", line 1705, in __call__\n    return self.func(*args)\n', '  File "C:\\Users\\Lenovo\\Documents\\git\\ntunhs_2020\\alg_20210610\\pyDEA\\pyDEA\\core\\gui_modules\\data_tab_frame_gui.py", line 247, in load_file\n    self.show_loaded_data(file_name)\n', '  File "C:\\Users\\Lenovo\\Documents\\git\\ntunhs_2020\\alg_20210610\\pyDEA\\pyDEA\\core\\gui_modules\\data_tab_frame_gui.py", line 337, in show_loaded_data\n    self.show_data(categories, coefficients, dmu_name)\n', '  File "C:\\Users\\Lenovo\\Documents\\git\\ntunhs_2020\\alg_20210610\\pyDEA\\pyDEA\\core\\gui_modules\\data_tab_frame_gui.py", line 374, in show_data\n    self.table.cells[0][0].insert(0, dmu_name)\n', '  File "C:\\ProgramData\\Anaconda3\\envs\\Recommandation\\lib\\tkinter\\__init__.py", line 2692, in insert\n    self.tk.call(self._w, \'insert\', index, string)\n', '_tkinter.TclError: wrong # args: should be ".!mainframe.!dataframe.!datatabframe.!labelframe.!tableframewithinputoutputbox.!styledcanvas.!frame.!selfvalidatingentry insert index text"\n']
2021-05-16 03:30:28,919 root         ERROR    ['Traceback (most recent call last):\n', '  File "C:\\ProgramData\\Anaconda3\\envs\\Recommandation\\lib\\tkinter\\__init__.py", line 1705, in __call__\n    return self.func(*args)\n', '  File "C:\\Users\\Lenovo\\Documents\\git\\ntunhs_2020\\alg_20210610\\pyDEA\\pyDEA\\core\\gui_modules\\data_tab_frame_gui.py", line 247, in load_file\n    self.show_loaded_data(file_name)\n', '  File "C:\\Users\\Lenovo\\Documents\\git\\ntunhs_2020\\alg_20210610\\pyDEA\\pyDEA\\core\\gui_modules\\data_tab_frame_gui.py", line 337, in show_loaded_data\n    self.show_data(categories, coefficients, dmu_name)\n', '  File "C:\\Users\\Lenovo\\Documents\\git\\ntunhs_2020\\alg_20210610\\pyDEA\\pyDEA\\core\\gui_modules\\data_tab_frame_gui.py", line 374, in show_data\n    self.table.cells[0][0].insert(0, dmu_name)\n', '  File "C:\\ProgramData\\Anaconda3\\envs\\Recommandation\\lib\\tkinter\\__init__.py", line 2692, in insert\n    self.tk.call(self._w, \'insert\', index, string)\n', '_tkinter.TclError: wrong # args: should be ".!mainframe.!dataframe.!datatabframe.!labelframe.!tableframewithinputoutputbox.!styledcanvas.!frame.!selfvalidatingentry insert index text"\n']
2021-05-16 03:34:14,512 root         INFO     Started solving given DEA model(s).
2021-05-16 03:34:14,513 root         INFO     Parameters: <DATA_FILE> = 'C:/Users/Lenovo/Desktop/DEA_example_data.csv', <INPUT_CATEGORIES> = 'I1;I2', <OUTPUT_CATEGORIES> = 'O1; O2', <DEA_FORM> = 'env', <RETURN_TO_SCALE> = 'VRS', <ORIENTATION> = 'input', <NON_DISCRETIONARY_CATEGORIES> = '', <WEAKLY_DISPOSAL_CATEGORIES> = '', <USE_SUPER_EFFICIENCY> = '', <ABS_WEIGHT_RESTRICTIONS> = '', <VIRTUAL_WEIGHT_RESTRICTIONS> = '', <PRICE_RATIO_RESTRICTIONS> = '', <MAXIMIZE_SLACKS> = '', <MULTIPLIER_MODEL_TOLERANCE> = '0', <OUTPUT_FILE> = '', <CATEGORICAL_CATEGORY> = '', <PEEL_THE_ONION> = ''
2021-05-16 03:34:18,451 root         INFO     Given DEA model(s) successfully solved.
