2021-05-16 03:22:30,740 root         INFO     pyDEA started as a GUI application.
2021-05-16 03:25:29,380 root         INFO     pyDEA started as a GUI application.
2021-05-16 03:27:35,555 root         ERROR    ['Traceback (most recent call last):\n', '  File "C:\\ProgramData\\Anaconda3\\envs\\Recommandation\\lib\\tkinter\\__init__.py", line 1705, in __call__\n    return self.func(*args)\n', '  File "C:\\Users\\Lenovo\\Documents\\git\\ntunhs_2020\\alg_20210610\\pyDEA\\pyDEA\\core\\gui_modules\\data_tab_frame_gui.py", line 247, in load_file\n    self.show_loaded_data(file_name)\n', '  File "C:\\Users\\Lenovo\\Documents\\git\\ntunhs_2020\\alg_20210610\\pyDEA\\pyDEA\\core\\gui_modules\\data_tab_frame_gui.py", line 337, in show_loaded_data\n    self.show_data(categories, coefficients, dmu_name)\n', '  File "C:\\Users\\Lenovo\\Documents\\git\\ntunhs_2020\\alg_20210610\\pyDEA\\pyDEA\\core\\gui_modules\\data_tab_frame_gui.py", line 374, in show_data\n    self.table.cells[0][0].insert(0, dmu_name)\n', '  File "C:\\ProgramData\\Anaconda3\\envs\\Recommandation\\lib\\tkinter\\__init__.py", line 2692, in insert\n    self.tk.call(self._w, \'insert\', index, string)\n', '_tkinter.TclError: wrong # args: should be ".!mainframe.!dataframe.!datatabframe.!labelframe.!tableframewithinputoutputbox.!styledcanvas.!frame.!selfvalidatingentry insert index text"\n']
2021-05-16 03:28:15,368 root         ERROR    ['Traceback (most recent call last):\n', '  File "C:\\ProgramData\\Anaconda3\\envs\\Recommandation\\lib\\tkinter\\__init__.py", line 1705, in __call__\n    return self.func(*args)\n', '  File "C:\\Users\\Lenovo\\Documents\\git\\ntunhs_2020\\alg_20210610\\pyDEA\\pyDEA\\core\\gui_modules\\data_tab_frame_gui.py", line 247, in load_file\n    self.show_loaded_data(file_name)\n', '  File "C:\\Users\\Lenovo\\Documents\\git\\ntunhs_2020\\alg_20210610\\pyDEA\\pyDEA\\core\\gui_modules\\data_tab_frame_gui.py", line 337, in show_loaded_data\n    self.show_data(categories, coefficients, dmu_name)\n', '  File "C:\\Users\\Lenovo\\Documents\\git\\ntunhs_2020\\alg_20210610\\pyDEA\\pyDEA\\core\\gui_modules\\data_tab_frame_gui.py", line 374, in show_data\n    self.table.cells[0][0].insert(0, dmu_name)\n', '  File "C:\\ProgramData\\Anaconda3\\envs\\Recommandation\\lib\\tkinter\\__init__.py", line 2692, in insert\n    self.tk.call(self._w, \'insert\', index, string)\n', '_tkinter.TclError: wrong # args: should be ".!mainframe.!dataframe.!datatabframe.!labelframe.!tableframewithinputoutputbox.!styledcanvas.!frame.!selfvalidatingentry insert index text"\n']
2021-05-16 03:28:21,339 root         ERROR    ['Traceback (most recent call last):\n', '  File "C:\\ProgramData\\Anaconda3\\envs\\Recommandation\\lib\\tkinter\\__init__.py", line 1705, in __call__\n    return self.func(*args)\n', '  File "C:\\Users\\Lenovo\\Documents\\git\\ntunhs_2020\\alg_20210610\\pyDEA\\pyDEA\\core\\gui_modules\\data_tab_frame_gui.py", line 247, in load_file\n    self.show_loaded_data(file_name)\n', '  File "C:\\Users\\Lenovo\\Documents\\git\\ntunhs_2020\\alg_20210610\\pyDEA\\pyDEA\\core\\gui_modules\\data_tab_frame_gui.py", line 337, in show_loaded_data\n    self.show_data(categories, coefficients, dmu_name)\n', '  File "C:\\Users\\Lenovo\\Documents\\git\\ntunhs_2020\\alg_20210610\\pyDEA\\pyDEA\\core\\gui_modules\\data_tab_frame_gui.py", line 374, in show_data\n    self.table.cells[0][0].insert(0, dmu_name)\n', '  File "C:\\ProgramData\\Anaconda3\\envs\\Recommandation\\lib\\tkinter\\__init__.py", line 2692, in insert\n    self.tk.call(self._w, \'insert\', index, string)\n', '_tkinter.TclError: wrong # args: should be ".!mainframe.!dataframe.!datatabframe.!labelframe.!tableframewithinputoutputbox.!styledcanvas.!frame.!selfvalidatingentry insert index text"\n']
2021-05-16 03:28:45,425 root         ERROR    ['Traceback (most recent call last):\n', '  File "C:\\ProgramData\\Anaconda3\\envs\\Recommandation\\lib\\tkinter\\__init__.py", line 1705, in __call__\n    return self.func(*args)\n', '  File "C:\\Users\\Lenovo\\Documents\\git\\ntunhs_2020\\alg_20210610\\pyDEA\\pyDEA\\core\\gui_modules\\data_tab_frame_gui.py", line 247, in load_file\n    self.show_loaded_data(file_name)\n', '  File "C:\\Users\\Lenovo\\Documents\\git\\ntunhs_2020\\alg_20210610\\pyDEA\\pyDEA\\core\\gui_modules\\data_tab_frame_gui.py", line 337, in show_loaded_data\n    self.show_data(categories, coefficients, dmu_name)\n', '  File "C:\\Users\\Lenovo\\Documents\\git\\ntunhs_2020\\alg_20210610\\pyDEA\\pyDEA\\core\\gui_modules\\data_tab_frame_gui.py", line 374, in show_data\n    self.table.cells[0][0].insert(0, dmu_name)\n', '  File "C:\\ProgramData\\Anaconda3\\envs\\Recommandation\\lib\\tkinter\\__init__.py", line 2692, in insert\n    self.tk.call(self._w, \'insert\', index, string)\n', '_tkinter.TclError: wrong # args: should be ".!mainframe.!dataframe.!datatabframe.!labelframe.!tableframewithinputoutputbox.!styledcanvas.!frame.!selfvalidatingentry insert index text"\n']
2021-05-16 03:29:20,346 root         ERROR    ['Traceback (most recent call last):\n', '  File "C:\\ProgramData\\Anaconda3\\envs\\Recommandation\\lib\\tkinter\\__init__.py", line 1705, in __call__\n    return self.func(*args)\n', '  File "C:\\Users\\Lenovo\\Documents\\git\\ntunhs_2020\\alg_20210610\\pyDEA\\pyDEA\\core\\gui_modules\\data_tab_frame_gui.py", line 247, in load_file\n    self.show_loaded_data(file_name)\n', '  File "C:\\Users\\Lenovo\\Documents\\git\\ntunhs_2020\\alg_20210610\\pyDEA\\pyDEA\\core\\gui_modules\\data_tab_frame_gui.py", line 337, in show_loaded_data\n    self.show_data(categories, coefficients, dmu_name)\n', '  File "C:\\Users\\Lenovo\\Documents\\git\\ntunhs_2020\\alg_20210610\\pyDEA\\pyDEA\\core\\gui_modules\\data_tab_frame_gui.py", line 374, in show_data\n    self.table.cells[0][0].insert(0, dmu_name)\n', '  File "C:\\ProgramData\\Anaconda3\\envs\\Recommandation\\lib\\tkinter\\__init__.py", line 2692, in insert\n    self.tk.call(self._w, \'insert\', index, string)\n', '_tkinter.TclError: wrong # args: should be ".!mainframe.!dataframe.!datatabframe.!labelframe.!tableframewithinputoutputbox.!styledcanvas.!frame.!selfvalidatingentry insert index text"\n']
2021-05-16 03:30:28,919 root         ERROR    ['Traceback (most recent call last):\n', '  File "C:\\ProgramData\\Anaconda3\\envs\\Recommandation\\lib\\tkinter\\__init__.py", line 1705, in __call__\n    return self.func(*args)\n', '  File "C:\\Users\\Lenovo\\Documents\\git\\ntunhs_2020\\alg_20210610\\pyDEA\\pyDEA\\core\\gui_modules\\data_tab_frame_gui.py", line 247, in load_file\n    self.show_loaded_data(file_name)\n', '  File "C:\\Users\\Lenovo\\Documents\\git\\ntunhs_2020\\alg_20210610\\pyDEA\\pyDEA\\core\\gui_modules\\data_tab_frame_gui.py", line 337, in show_loaded_data\n    self.show_data(categories, coefficients, dmu_name)\n', '  File "C:\\Users\\Lenovo\\Documents\\git\\ntunhs_2020\\alg_20210610\\pyDEA\\pyDEA\\core\\gui_modules\\data_tab_frame_gui.py", line 374, in show_data\n    self.table.cells[0][0].insert(0, dmu_name)\n', '  File "C:\\ProgramData\\Anaconda3\\envs\\Recommandation\\lib\\tkinter\\__init__.py", line 2692, in insert\n    self.tk.call(self._w, \'insert\', index, string)\n', '_tkinter.TclError: wrong # args: should be ".!mainframe.!dataframe.!datatabframe.!labelframe.!tableframewithinputoutputbox.!styledcanvas.!frame.!selfvalidatingentry insert index text"\n']
2021-05-16 03:34:14,512 root         INFO     Started solving given DEA model(s).
2021-05-16 03:34:14,513 root         INFO     Parameters: <DATA_FILE> = 'C:/Users/Lenovo/Desktop/DEA_example_data.csv', <INPUT_CATEGORIES> = 'I1;I2', <OUTPUT_CATEGORIES> = 'O1; O2', <DEA_FORM> = 'env', <RETURN_TO_SCALE> = 'VRS', <ORIENTATION> = 'input', <NON_DISCRETIONARY_CATEGORIES> = '', <WEAKLY_DISPOSAL_CATEGORIES> = '', <USE_SUPER_EFFICIENCY> = '', <ABS_WEIGHT_RESTRICTIONS> = '', <VIRTUAL_WEIGHT_RESTRICTIONS> = '', <PRICE_RATIO_RESTRICTIONS> = '', <MAXIMIZE_SLACKS> = '', <MULTIPLIER_MODEL_TOLERANCE> = '0', <OUTPUT_FILE> = '', <CATEGORICAL_CATEGORY> = '', <PEEL_THE_ONION> = ''
2021-05-16 03:34:18,451 root         INFO     Given DEA model(s) successfully solved.
2021-06-06 03:04:29,349 root         INFO     pyDEA started as a GUI application.
2021-06-06 18:03:37,018 root         INFO     Started solving given DEA model(s).
2021-06-06 18:03:37,020 root         INFO     Parameters: <DATA_FILE> = '', <INPUT_CATEGORIES> = '', <OUTPUT_CATEGORIES> = '', <DEA_FORM> = 'env', <RETURN_TO_SCALE> = 'VRS', <ORIENTATION> = 'input', <NON_DISCRETIONARY_CATEGORIES> = '', <WEAKLY_DISPOSAL_CATEGORIES> = '', <USE_SUPER_EFFICIENCY> = '', <ABS_WEIGHT_RESTRICTIONS> = '', <VIRTUAL_WEIGHT_RESTRICTIONS> = '', <PRICE_RATIO_RESTRICTIONS> = '', <MAXIMIZE_SLACKS> = '', <MULTIPLIER_MODEL_TOLERANCE> = '0', <OUTPUT_FILE> = '', <CATEGORICAL_CATEGORY> = '', <PEEL_THE_ONION> = ''
2021-06-06 18:03:37,022 root         ERROR    Some DMUs have the same name
2021-06-06 18:05:29,466 root         ERROR    ['Traceback (most recent call last):\n', '  File "C:\\ProgramData\\Anaconda3\\envs\\Recommandation\\lib\\tkinter\\__init__.py", line 1705, in __call__\n    return self.func(*args)\n', '  File "C:\\Users\\Lenovo\\Documents\\git\\ntunhs_2020\\alg_20210610\\pyDEA\\pyDEA\\core\\gui_modules\\data_tab_frame_gui.py", line 247, in load_file\n    self.show_loaded_data(file_name)\n', '  File "C:\\Users\\Lenovo\\Documents\\git\\ntunhs_2020\\alg_20210610\\pyDEA\\pyDEA\\core\\gui_modules\\data_tab_frame_gui.py", line 337, in show_loaded_data\n    self.show_data(categories, coefficients, dmu_name)\n', '  File "C:\\Users\\Lenovo\\Documents\\git\\ntunhs_2020\\alg_20210610\\pyDEA\\pyDEA\\core\\gui_modules\\data_tab_frame_gui.py", line 374, in show_data\n    self.table.cells[0][0].insert(0, dmu_name)\n', '  File "C:\\ProgramData\\Anaconda3\\envs\\Recommandation\\lib\\tkinter\\__init__.py", line 2692, in insert\n    self.tk.call(self._w, \'insert\', index, string)\n', '_tkinter.TclError: wrong # args: should be ".!mainframe.!dataframe.!datatabframe.!labelframe.!tableframewithinputoutputbox.!styledcanvas.!frame.!selfvalidatingentry insert index text"\n']
2021-06-06 18:05:41,027 root         ERROR    ['Traceback (most recent call last):\n', '  File "C:\\ProgramData\\Anaconda3\\envs\\Recommandation\\lib\\tkinter\\__init__.py", line 1705, in __call__\n    return self.func(*args)\n', '  File "C:\\Users\\Lenovo\\Documents\\git\\ntunhs_2020\\alg_20210610\\pyDEA\\pyDEA\\core\\gui_modules\\data_tab_frame_gui.py", line 247, in load_file\n    self.show_loaded_data(file_name)\n', '  File "C:\\Users\\Lenovo\\Documents\\git\\ntunhs_2020\\alg_20210610\\pyDEA\\pyDEA\\core\\gui_modules\\data_tab_frame_gui.py", line 337, in show_loaded_data\n    self.show_data(categories, coefficients, dmu_name)\n', '  File "C:\\Users\\Lenovo\\Documents\\git\\ntunhs_2020\\alg_20210610\\pyDEA\\pyDEA\\core\\gui_modules\\data_tab_frame_gui.py", line 374, in show_data\n    self.table.cells[0][0].insert(0, dmu_name)\n', '  File "C:\\ProgramData\\Anaconda3\\envs\\Recommandation\\lib\\tkinter\\__init__.py", line 2692, in insert\n    self.tk.call(self._w, \'insert\', index, string)\n', '_tkinter.TclError: wrong # args: should be ".!mainframe.!dataframe.!datatabframe.!labelframe.!tableframewithinputoutputbox.!styledcanvas.!frame.!selfvalidatingentry insert index text"\n']
2021-06-06 18:06:47,862 root         ERROR    ['Traceback (most recent call last):\n', '  File "C:\\ProgramData\\Anaconda3\\envs\\Recommandation\\lib\\tkinter\\__init__.py", line 1705, in __call__\n    return self.func(*args)\n', '  File "C:\\Users\\Lenovo\\Documents\\git\\ntunhs_2020\\alg_20210610\\pyDEA\\pyDEA\\core\\gui_modules\\data_tab_frame_gui.py", line 247, in load_file\n    self.show_loaded_data(file_name)\n', '  File "C:\\Users\\Lenovo\\Documents\\git\\ntunhs_2020\\alg_20210610\\pyDEA\\pyDEA\\core\\gui_modules\\data_tab_frame_gui.py", line 337, in show_loaded_data\n    self.show_data(categories, coefficients, dmu_name)\n', '  File "C:\\Users\\Lenovo\\Documents\\git\\ntunhs_2020\\alg_20210610\\pyDEA\\pyDEA\\core\\gui_modules\\data_tab_frame_gui.py", line 374, in show_data\n    self.table.cells[0][0].insert(0, dmu_name)\n', '  File "C:\\ProgramData\\Anaconda3\\envs\\Recommandation\\lib\\tkinter\\__init__.py", line 2692, in insert\n    self.tk.call(self._w, \'insert\', index, string)\n', '_tkinter.TclError: wrong # args: should be ".!mainframe.!dataframe.!datatabframe.!labelframe.!tableframewithinputoutputbox.!styledcanvas.!frame.!selfvalidatingentry insert index text"\n']
2021-06-06 18:07:27,503 root         ERROR    ['Traceback (most recent call last):\n', '  File "C:\\ProgramData\\Anaconda3\\envs\\Recommandation\\lib\\tkinter\\__init__.py", line 1705, in __call__\n    return self.func(*args)\n', '  File "C:\\Users\\Lenovo\\Documents\\git\\ntunhs_2020\\alg_20210610\\pyDEA\\pyDEA\\core\\gui_modules\\data_tab_frame_gui.py", line 247, in load_file\n    self.show_loaded_data(file_name)\n', '  File "C:\\Users\\Lenovo\\Documents\\git\\ntunhs_2020\\alg_20210610\\pyDEA\\pyDEA\\core\\gui_modules\\data_tab_frame_gui.py", line 337, in show_loaded_data\n    self.show_data(categories, coefficients, dmu_name)\n', '  File "C:\\Users\\Lenovo\\Documents\\git\\ntunhs_2020\\alg_20210610\\pyDEA\\pyDEA\\core\\gui_modules\\data_tab_frame_gui.py", line 374, in show_data\n    self.table.cells[0][0].insert(0, dmu_name)\n', '  File "C:\\ProgramData\\Anaconda3\\envs\\Recommandation\\lib\\tkinter\\__init__.py", line 2692, in insert\n    self.tk.call(self._w, \'insert\', index, string)\n', '_tkinter.TclError: wrong # args: should be ".!mainframe.!dataframe.!datatabframe.!labelframe.!tableframewithinputoutputbox.!styledcanvas.!frame.!selfvalidatingentry insert index text"\n']
2021-06-06 18:07:33,232 root         ERROR    ['Traceback (most recent call last):\n', '  File "C:\\ProgramData\\Anaconda3\\envs\\Recommandation\\lib\\tkinter\\__init__.py", line 1705, in __call__\n    return self.func(*args)\n', '  File "C:\\Users\\Lenovo\\Documents\\git\\ntunhs_2020\\alg_20210610\\pyDEA\\pyDEA\\core\\gui_modules\\data_tab_frame_gui.py", line 247, in load_file\n    self.show_loaded_data(file_name)\n', '  File "C:\\Users\\Lenovo\\Documents\\git\\ntunhs_2020\\alg_20210610\\pyDEA\\pyDEA\\core\\gui_modules\\data_tab_frame_gui.py", line 337, in show_loaded_data\n    self.show_data(categories, coefficients, dmu_name)\n', '  File "C:\\Users\\Lenovo\\Documents\\git\\ntunhs_2020\\alg_20210610\\pyDEA\\pyDEA\\core\\gui_modules\\data_tab_frame_gui.py", line 374, in show_data\n    self.table.cells[0][0].insert(0, dmu_name)\n', '  File "C:\\ProgramData\\Anaconda3\\envs\\Recommandation\\lib\\tkinter\\__init__.py", line 2692, in insert\n    self.tk.call(self._w, \'insert\', index, string)\n', '_tkinter.TclError: wrong # args: should be ".!mainframe.!dataframe.!datatabframe.!labelframe.!tableframewithinputoutputbox.!styledcanvas.!frame.!selfvalidatingentry insert index text"\n']
2021-06-06 18:07:38,689 root         ERROR    ['Traceback (most recent call last):\n', '  File "C:\\ProgramData\\Anaconda3\\envs\\Recommandation\\lib\\tkinter\\__init__.py", line 1705, in __call__\n    return self.func(*args)\n', '  File "C:\\Users\\Lenovo\\Documents\\git\\ntunhs_2020\\alg_20210610\\pyDEA\\pyDEA\\core\\gui_modules\\data_tab_frame_gui.py", line 247, in load_file\n    self.show_loaded_data(file_name)\n', '  File "C:\\Users\\Lenovo\\Documents\\git\\ntunhs_2020\\alg_20210610\\pyDEA\\pyDEA\\core\\gui_modules\\data_tab_frame_gui.py", line 337, in show_loaded_data\n    self.show_data(categories, coefficients, dmu_name)\n', '  File "C:\\Users\\Lenovo\\Documents\\git\\ntunhs_2020\\alg_20210610\\pyDEA\\pyDEA\\core\\gui_modules\\data_tab_frame_gui.py", line 374, in show_data\n    self.table.cells[0][0].insert(0, dmu_name)\n', '  File "C:\\ProgramData\\Anaconda3\\envs\\Recommandation\\lib\\tkinter\\__init__.py", line 2692, in insert\n    self.tk.call(self._w, \'insert\', index, string)\n', '_tkinter.TclError: wrong # args: should be ".!mainframe.!dataframe.!datatabframe.!labelframe.!tableframewithinputoutputbox.!styledcanvas.!frame.!selfvalidatingentry insert index text"\n']
2021-06-06 18:11:25,554 root         INFO     Started solving given DEA model(s).
2021-06-06 18:11:25,554 root         INFO     Parameters: <DATA_FILE> = 'C:/Users/Lenovo/Documents/git/ntunhs_2020/alg_20210610/pyDEA/tests/test_file_for_data_save.xlsx', <INPUT_CATEGORIES> = 'price or cost', <OUTPUT_CATEGORIES> = 'looks;storage space;camera quality', <DEA_FORM> = 'env', <RETURN_TO_SCALE> = 'VRS', <ORIENTATION> = 'input', <NON_DISCRETIONARY_CATEGORIES> = '', <WEAKLY_DISPOSAL_CATEGORIES> = '', <USE_SUPER_EFFICIENCY> = '', <ABS_WEIGHT_RESTRICTIONS> = '', <VIRTUAL_WEIGHT_RESTRICTIONS> = '', <PRICE_RATIO_RESTRICTIONS> = '', <MAXIMIZE_SLACKS> = '', <MULTIPLIER_MODEL_TOLERANCE> = '0', <OUTPUT_FILE> = '', <CATEGORICAL_CATEGORY> = '', <PEEL_THE_ONION> = ''
2021-06-06 18:11:25,871 root         INFO     Given DEA model(s) successfully solved.
2021-06-06 18:11:52,039 root         INFO     Started solving given DEA model(s).
2021-06-06 18:11:52,039 root         INFO     Parameters: <DATA_FILE> = 'C:/Users/Lenovo/Documents/git/ntunhs_2020/alg_20210610/pyDEA/tests/test_file_for_data_save.xlsx', <INPUT_CATEGORIES> = 'price or cost', <OUTPUT_CATEGORIES> = 'looks;storage space;camera quality', <DEA_FORM> = 'env', <RETURN_TO_SCALE> = 'CRS', <ORIENTATION> = 'input', <NON_DISCRETIONARY_CATEGORIES> = '', <WEAKLY_DISPOSAL_CATEGORIES> = '', <USE_SUPER_EFFICIENCY> = '', <ABS_WEIGHT_RESTRICTIONS> = '', <VIRTUAL_WEIGHT_RESTRICTIONS> = '', <PRICE_RATIO_RESTRICTIONS> = '', <MAXIMIZE_SLACKS> = '', <MULTIPLIER_MODEL_TOLERANCE> = '0', <OUTPUT_FILE> = '', <CATEGORICAL_CATEGORY> = '', <PEEL_THE_ONION> = ''
2021-06-06 18:11:52,233 root         INFO     Given DEA model(s) successfully solved.
2021-06-06 18:59:11,409 root         INFO     Started solving given DEA model(s).
2021-06-06 18:59:11,409 root         INFO     Parameters: <DATA_FILE> = 'C:/Users/Lenovo/Documents/git/ntunhs_2020/alg_20210610/dea_example.xlsx', <INPUT_CATEGORIES> = 'price_or_cost;', <OUTPUT_CATEGORIES> = 'looks;storage_space;camera_quality;', <DEA_FORM> = 'env', <RETURN_TO_SCALE> = 'CRS', <ORIENTATION> = 'input', <NON_DISCRETIONARY_CATEGORIES> = '', <WEAKLY_DISPOSAL_CATEGORIES> = '', <USE_SUPER_EFFICIENCY> = '', <ABS_WEIGHT_RESTRICTIONS> = '', <VIRTUAL_WEIGHT_RESTRICTIONS> = '', <PRICE_RATIO_RESTRICTIONS> = '', <MAXIMIZE_SLACKS> = '', <MULTIPLIER_MODEL_TOLERANCE> = '0', <OUTPUT_FILE> = '', <CATEGORICAL_CATEGORY> = '', <PEEL_THE_ONION> = ''
2021-06-06 18:59:11,633 root         INFO     Given DEA model(s) successfully solved.
2021-06-06 19:08:44,100 root         INFO     pyDEA exited.
2021-06-06 23:54:55,555 root         INFO     pyDEA started as a GUI application.
2021-06-06 23:56:29,030 root         INFO     Started solving given DEA model(s).
2021-06-06 23:56:29,031 root         INFO     Parameters: <DATA_FILE> = 'tests/DEA_example2_data.csv', <INPUT_CATEGORIES> = 'I1; I2; I3', <OUTPUT_CATEGORIES> = 'O1; O2', <DEA_FORM> = 'env', <RETURN_TO_SCALE> = 'VRS', <ORIENTATION> = 'input', <NON_DISCRETIONARY_CATEGORIES> = '', <WEAKLY_DISPOSAL_CATEGORIES> = '', <USE_SUPER_EFFICIENCY> = '', <ABS_WEIGHT_RESTRICTIONS> = '', <VIRTUAL_WEIGHT_RESTRICTIONS> = '', <PRICE_RATIO_RESTRICTIONS> = '', <MAXIMIZE_SLACKS> = '', <MULTIPLIER_MODEL_TOLERANCE> = '0', <OUTPUT_FILE> = '', <CATEGORICAL_CATEGORY> = '', <PEEL_THE_ONION> = ''
2021-06-06 23:56:31,880 root         INFO     Given DEA model(s) successfully solved.
2021-06-06 23:57:08,745 root         INFO     pyDEA exited.
2021-06-06 23:57:11,973 root         INFO     pyDEA started as a GUI application.
2021-06-06 23:57:38,512 root         INFO     Started solving given DEA model(s).
2021-06-06 23:57:38,513 root         INFO     Parameters: <DATA_FILE> = 'C:/Users/Lenovo/Documents/git/ntunhs_2020/alg_20210610/dea_example.xlsx', <INPUT_CATEGORIES> = 'price or cost', <OUTPUT_CATEGORIES> = 'looks;storage space;camera quality', <DEA_FORM> = 'env', <RETURN_TO_SCALE> = 'CRS', <ORIENTATION> = 'input', <NON_DISCRETIONARY_CATEGORIES> = '', <WEAKLY_DISPOSAL_CATEGORIES> = '', <USE_SUPER_EFFICIENCY> = '', <ABS_WEIGHT_RESTRICTIONS> = '', <VIRTUAL_WEIGHT_RESTRICTIONS> = '', <PRICE_RATIO_RESTRICTIONS> = '', <MAXIMIZE_SLACKS> = '', <MULTIPLIER_MODEL_TOLERANCE> = '0', <OUTPUT_FILE> = '', <CATEGORICAL_CATEGORY> = '', <PEEL_THE_ONION> = ''
2021-06-06 23:57:38,714 root         INFO     Given DEA model(s) successfully solved.
2021-06-06 23:59:31,103 root         INFO     Started solving given DEA model(s).
2021-06-06 23:59:31,104 root         INFO     Parameters: <DATA_FILE> = 'tests/DEA data Harish.xlsx', <INPUT_CATEGORIES> = 'Expenditure/sealed km (NZD)', <OUTPUT_CATEGORIES> = 'PII; SCI; STE; Urban Roads (%); VkT (km)', <DEA_FORM> = 'env', <RETURN_TO_SCALE> = 'VRS', <ORIENTATION> = 'output', <NON_DISCRETIONARY_CATEGORIES> = '', <WEAKLY_DISPOSAL_CATEGORIES> = '', <USE_SUPER_EFFICIENCY> = '', <ABS_WEIGHT_RESTRICTIONS> = 'Urban Roads (%)<=0.003', <VIRTUAL_WEIGHT_RESTRICTIONS> = '', <PRICE_RATIO_RESTRICTIONS> = '', <MAXIMIZE_SLACKS> = '', <MULTIPLIER_MODEL_TOLERANCE> = '0', <OUTPUT_FILE> = '', <CATEGORICAL_CATEGORY> = '', <PEEL_THE_ONION> = ''
2021-06-06 23:59:33,985 root         INFO     Given DEA model(s) successfully solved.
2021-06-07 00:00:01,766 root         INFO     Started solving given DEA model(s).
2021-06-07 00:00:01,766 root         INFO     Parameters: <DATA_FILE> = 'tests\DEA data Harish.xlsx', <INPUT_CATEGORIES> = 'Expenditure/sealed km (NZD)', <OUTPUT_CATEGORIES> = 'PII; SCI; STE; Urban Roads (%); VkT (km)', <DEA_FORM> = 'env', <RETURN_TO_SCALE> = 'VRS', <ORIENTATION> = 'output', <NON_DISCRETIONARY_CATEGORIES> = '', <WEAKLY_DISPOSAL_CATEGORIES> = '', <USE_SUPER_EFFICIENCY> = '', <ABS_WEIGHT_RESTRICTIONS> = 'Urban Roads (%)<=0.003', <VIRTUAL_WEIGHT_RESTRICTIONS> = '', <PRICE_RATIO_RESTRICTIONS> = '', <MAXIMIZE_SLACKS> = '', <MULTIPLIER_MODEL_TOLERANCE> = '0', <OUTPUT_FILE> = '', <CATEGORICAL_CATEGORY> = '', <PEEL_THE_ONION> = ''
2021-06-07 00:00:04,925 root         INFO     Given DEA model(s) successfully solved.
2021-06-07 00:00:50,605 root         INFO     pyDEA exited.
2021-06-07 00:00:53,503 root         INFO     pyDEA started as a GUI application.
2021-06-07 00:01:26,192 root         INFO     pyDEA exited.
